Workbook

Sheet Look up table
A1: Dec | B1: Hex | C1: Character
A2: 0 | B2: =DEC2HEX(A2) -> 0 | C2: [NUL]
A3: 1 | B3: =DEC2HEX(A3) -> 1 | C3: [SOH]
A4: 2 | B4: =DEC2HEX(A4) -> 2 | C4: [STX]
A5: 3 | B5: =DEC2HEX(A5) -> 3 | C5: [ETX]
A6: 4 | B6: =DEC2HEX(A6) -> 4 | C6: [EOT]
A7: 5 | B7: =DEC2HEX(A7) -> 5 | C7: [ENQ]
A8: 6 | B8: =DEC2HEX(A8) -> 6 | C8: [ACK]
A9: 7 | B9: =DEC2HEX(A9) -> 7 | C9: [BEL]
A10: 8 | B10: =DEC2HEX(A10) -> 8 | C10: [BS]
A11: 9 | B11: =DEC2HEX(A11) -> 9 | C11: [HT]
A12: 10 | B12: =DEC2HEX(A12) -> A | C12: [LF]
A13: 11 | B13: =DEC2HEX(A13) -> B | C13: [VT]
... A40: 38 | B40: =DEC2HEX(A40) -> 26 | C40: &
A41: 39 | B41: =DEC2HEX(A41) -> 27
A42: 40 | B42: =DEC2HEX(A42) -> 28 | C42: (
A43: 41 | B43: =DEC2HEX(A43) -> 29 | C43: )
A44: 42 | B44: =DEC2HEX(A44) -> 2A | C44: *
A45: 43 | B45: =DEC2HEX(A45) -> 2B | C45: +
A46: 44 | B46: =DEC2HEX(A46) -> 2C | C46: ,
A47: 45 | B47: =DEC2HEX(A47) -> 2D | C47: -
A48: 46 | B48: =DEC2HEX(A48) -> 2E | C48: .
A49: 47 | B49: =DEC2HEX(A49) -> 2F | C49: /
A50: 48 | B50: =DEC2HEX(A50) -> 30 | C50: 0
A51: 49 | B51: =DEC2HEX(A51) -> 31 | C51: 1
A52: 50 | B52: =DEC2HEX(A52) -> 32 | C52: 2
A53: 51 | B53: =DEC2HEX(A53) -> 33 | C53: 3
A54: 52 | B54: =DEC2HEX(A54) -> 34 | C54: 4
A55: 53 | B55: =DEC2HEX(A55) -> 35 | C55: 5
A56: 54 | B56: =DEC2HEX(A56) -> 36 | C56: 6
A57: 55 | B57: =DEC2HEX(A57) -> 37 | C57: 7
A58: 56 | B58: =DEC2HEX(A58) -> 38 | C58: 8
A59: 57 | B59: =DEC2HEX(A59) -> 39 | C59: 9
A60: 58 | B60: =DEC2HEX(A60) -> 3A | C60: :
A61: 59 | B61: =DEC2HEX(A61) -> 3B | C61: ;
A62: 60 | B62: =DEC2HEX(A62) -> 3C | C62: <
A63: 61 | B63: =DEC2HEX(A63) -> 3D | C63: =
A64: 62 | B64: =DEC2HEX(A64) -> 3E | C64: >
A65: 63 | B65: =DEC2HEX(A65) -> 3F | C65: ?
A66: 64 | B66: =DEC2HEX(A66) -> 40 | C66: @
...

Sheet Unicode Decoder
A1: Binary | B1: Hex | C1: Unicode
A2: 1000110 | B2: =BIN2HEX(A2) -> 46 | C2: =_xlfn.XLOOKUP(B2,'Look up table'!B2:B129,'Look up table'!C2:C129) -> F | D2: <- Use XLOOKUP here with the table in the Look up table worksheet
A3: 1101100 | B3: =BIN2HEX(A3) -> 6C | C3: =_xlfn.XLOOKUP(B3,'Look up table'!B3:B130,'Look up table'!C3:C130) -> l
A4: 1111001 | B4: =BIN2HEX(A4) -> 79 | C4: =_xlfn.XLOOKUP(B4,'Look up table'!B4:B131,'Look up table'!C4:C131) -> y
A5: 1101001 | B5: =BIN2HEX(A5) -> 69 | C5: =_xlfn.XLOOKUP(B5,'Look up table'!B5:B132,'Look up table'!C5:C132) -> i
A6: 1101110 | B6: =BIN2HEX(A6) -> 6E | C6: =_xlfn.XLOOKUP(B6,'Look up table'!B6:B133,'Look up table'!C6:C133) -> n
A7: 1100111 | B7: =BIN2HEX(A7) -> 67 | C7: =_xlfn.XLOOKUP(B7,'Look up table'!B7:B134,'Look up table'!C7:C134) -> g
A8: 100000 | B8: =BIN2HEX(A8) -> 20 | C8: =_xlfn.XLOOKUP(B8,'Look up table'!B8:B135,'Look up table'!C8:C135) -> [SP]
A9: 1000011 | B9: =BIN2HEX(A9) -> 43 | C9: =_xlfn.XLOOKUP(B9,'Look up table'!B9:B136,'Look up table'!C9:C136) -> C
A10: 1101001 | B10: =BIN2HEX(A10) -> 69 | C10: =_xlfn.XLOOKUP(B10,'Look up table'!B10:B137,'Look up table'!C10:C137) -> i
A11: 1110010 | B11: =BIN2HEX(A11) -> 72 | C11: =_xlfn.XLOOKUP(B11,'Look up table'!B11:B138,'Look up table'!C11:C138) -> r
A12: 1100011 | B12: =BIN2HEX(A12) -> 63 | C12: =_xlfn.XLOOKUP(B12,'Look up table'!B12:B139,'Look up table'!C12:C139) -> c
A13: 1110101 | B13: =BIN2HEX(A13) -> 75 | C13: =_xlfn.XLOOKUP(B13,'Look up table'!B13:B140,'Look up table'!C13:C140) -> u
A14: 1110011 | B14: =BIN2HEX(A14) -> 73 | C14: =_xlfn.XLOOKUP(B14,'Look up table'!B14:B141,'Look up table'!C14:C141) -> s
... A17: 101001 | B17: =BIN2HEX(A17) -> 29 | C17: =_xlfn.XLOOKUP(B17,'Look up table'!B17:B144,'Look up table'!C17:C144) -> )
